Workbook

Sheet countries
A1: Id | B1: Name | C1: CountryCode | D1: FriendlyName
A2: 1 | B2: ALBANIA | C2: AL | D2: Albania | E2: ="new Models.Country() {Name = """&B2&""", Code = """&C2&""", Id ="&A2&"}," -> new Models.Country() {Name = "ALBANIA", Code = "AL", Id =1},
A3: =A2+1 -> 2 | B3: ALGERIA | C3: DZ | D3: Algeria | E3: ="new Models.Country() {Name = """&B3&""", Code = """&C3&""", Id ="&A3&"}," -> new Models.Country() {Name = "ALGERIA", Code = "DZ", Id =2},
A4: =A3+1 -> 3 | B4: ANDORRA | C4: AD | D4: Andorra | E4: ="new Models.Country() {Name = """&B4&""", Code = """&C4&""", Id ="&A4&"}," -> new Models.Country() {Name = "ANDORRA", Code = "AD", Id =3},
A5: =A4+1 -> 4 | B5: ANGOLA | C5: AO | D5: Angola | E5: ="new Models.Country() {Name = """&B5&""", Code = """&C5&""", Id ="&A5&"}," -> new Models.Country() {Name = "ANGOLA", Code = "AO", Id =4},
A6: =A5+1 -> 5 | B6: ANGUILLA | C6: AI | D6: Anguilla | E6: ="new Models.Country() {Name = """&B6&""", Code = """&C6&""", Id ="&A6&"}," -> new Models.Country() {Name = "ANGUILLA", Code = "AI", Id =5},
A7: =A6+1 -> 6 | B7: ANTIGUA & BARBUDA | C7: AG | D7: Antigua & Barbuda | E7: ="new Models.Country() {Name = """&B7&""", Code = """&C7&""", Id ="&A7&"}," -> new Models.Country() {Name = "ANTIGUA & BARBUDA", Code = "AG", Id =6},
A8: =A7+1 -> 7 | B8: ARGENTINA | C8: AR | D8: Argentina | E8: ="new Models.Country() {Name = """&B8&""", Code = """&C8&""", Id ="&A8&"}," -> new Models.Country() {Name = "ARGENTINA", Code = "AR", Id =7},
A9: =A8+1 -> 8 | B9: ARMENIA | C9: AM | D9: Armenia | E9: ="new Models.Country() {Name = """&B9&""", Code = """&C9&""", Id ="&A9&"}," -> new Models.Country() {Name = "ARMENIA", Code = "AM", Id =8},
A10: =A9+1 -> 9 | B10: ARUBA | C10: AW | D10: Aruba | E10: ="new Models.Country() {Name = """&B10&""", Code = """&C10&""", Id ="&A10&"}," -> new Models.Country() {Name = "ARUBA", Code = "AW", Id =9},
A11: =A10+1 -> 10 | B11: AUSTRALIA | C11: AU | D11: Australia | E11: ="new Models.Country() {Name = """&B11&""", Code = """&C11&""", Id ="&A11&"}," -> new Models.Country() {Name = "AUSTRALIA", Code = "AU", Id =10},
A12: =A11+1 -> 11 | B12: AUSTRIA | C12: AT | D12: Austria | E12: ="new Models.Country() {Name = """&B12&""", Code = """&C12&""", Id ="&A12&"}," -> new Models.Country() {Name = "AUSTRIA", Code = "AT", Id =11},
A13: =A12+1 -> 12 | B13: AZERBAIJAN | C13: AZ | D13: Azerbaijan | E13: ="new Models.Country() {Name = """&B13&""", Code = """&C13&""", Id ="&A13&"}," -> new Models.Country() {Name = "AZERBAIJAN", Code = "AZ", Id =12},
A14: =A13+1 -> 13 | B14: BAHAMAS | C14: BS | D14: Bahamas | E14: ="new Models.Country() {Name = """&B14&""", Code = """&C14&""", Id ="&A14&"}," -> new Models.Country() {Name = "BAHAMAS", Code = "BS", Id =13},
... A202: =A201+1 -> 201 | B202: ZIMBABWE | C202: ZW | D202: Zimbabwe | E202: ="new Models.Country() {Name = """&B202&""", Code = """&C202&""", Id ="&A202&"}," -> new Models.Country() {Name = "ZIMBABWE", Code = "ZW", Id =201},

Sheet Country_WorkingSheet
A1: FriendlyName | B1: Id | C1: Name | D1: CountryCode
A2: Albania | B2: 1 | C2: ALBANIA | D2: AL
A3: Algeria | B3: 2 | C3: ALGERIA | D3: DZ
A4: Andorra | B4: 3 | C4: ANDORRA | D4: AD
A5: Angola | B5: 4 | C5: ANGOLA | D5: AO
A6: Anguilla | B6: 5 | C6: ANGUILLA | D6: AI
A7: Antigua & Barbuda | B7: 6 | C7: ANTIGUA & BARBUDA | D7: AG
A8: Argentina | B8: 7 | C8: ARGENTINA | D8: AR
A9: Armenia | B9: 8 | C9: ARMENIA | D9: AM
A10: Aruba | B10: 9 | C10: ARUBA | D10: AW
A11: Australia | B11: 10 | C11: AUSTRALIA | D11: AU
A12: Austria | B12: 11 | C12: AUSTRIA | D12: AT
A13: Azerbaijan | B13: 12 | C13: AZERBAIJAN | D13: AZ
... A202: Zimbabwe | B202: 201 | C202: ZIMBABWE | D202: ZW

Sheet State_Provinces
A1: Country | B1: Name | C1: Code | D1: Type | E1: LocalName | F1: CountryId
A2: Argentina | B2: Buenos Aires (Ciudad) | C2: CIUDAD AUTÓNOMA DE BUENOS AIRES | D2: Province | F2: =VLOOKUP(A2,Country_WorkingSheet!$A$1:$D$202,2,FALSE) -> 7
A3: Argentina | B3: Buenos Aires (Provincia) | C3: BUENOS AIRES | D3: Province | F3: =VLOOKUP(A3,Country_WorkingSheet!$A$1:$D$202,2,FALSE) -> 7
A4: Argentina | B4: Catamarca | C4: CATAMARCA | D4: Province | F4: =VLOOKUP(A4,Country_WorkingSheet!$A$1:$D$202,2,FALSE) -> 7
A5: Argentina | B5: Chaco | C5: CHACO | D5: Province | F5: =VLOOKUP(A5,Country_WorkingSheet!$A$1:$D$202,2,FALSE) -> 7
A6: Argentina | B6: Chubut | C6: CHUBUT | D6: Province | F6: =VLOOKUP(A6,Country_WorkingSheet!$A$1:$D$202,2,FALSE) -> 7
A7: Argentina | B7: Corrientes | C7: CORRIENTES | D7: Province | F7: =VLOOKUP(A7,Country_WorkingSheet!$A$1:$D$202,2,FALSE) -> 7
A8: Argentina | B8: Córdoba | C8: CÓRDOBA | D8: Province | F8: =VLOOKUP(A8,Country_WorkingSheet!$A$1:$D$202,2,FALSE) -> 7
A9: Argentina | B9: Entre Ríos | C9: ENTRE RÍOS | D9: Province | F9: =VLOOKUP(A9,Country_WorkingSheet!$A$1:$D$202,2,FALSE) -> 7
A10: Argentina | B10: Formosa | C10: FORMOSA | D10: Province | F10: =VLOOKUP(A10,Country_WorkingSheet!$A$1:$D$202,2,FALSE) -> 7
A11: Argentina | B11: Jujuy | C11: JUJUY | D11: Province | F11: =VLOOKUP(A11,Country_WorkingSheet!$A$1:$D$202,2,FALSE) -> 7
A12: Argentina | B12: La Pampa | C12: LA PAMPA | D12: Province | F12: =VLOOKUP(A12,Country_WorkingSheet!$A$1:$D$202,2,FALSE) -> 7
A13: Argentina | B13: La Rioja | C13: LA RIOJA | D13: Province | F13: =VLOOKUP(A13,Country_WorkingSheet!$A$1:$D$202,2,FALSE) -> 7
... A65: Canada | B65: Yukon | C65: YT | D65: Province | F65: =VLOOKUP(A65,Country_WorkingSheet!$A$1:$D$202,2,FALSE) -> 33
A66: China | B66: Anhui Sheng | C66: CN-AH | D66: Province | E66: 安徽省 (Ānhuī Shěng) | F66: =VLOOKUP(A66,Country_WorkingSheet!$A$1:$D$202,2,FALSE) -> 38
A67: China | B67: Beijing Shi | C67: CN-BJ | D67: Municipality | E67: 北京市 (Běijīng Shì) | F67: =VLOOKUP(A67,Country_WorkingSheet!$A$1:$D$202,2,FALSE) -> 38
A68: China | B68: Chongqing Shi | C68: CN-CQ | D68: Municipality | E68: 重庆市 (Chóngqìng Shì) | F68: =VLOOKUP(A68,Country_WorkingSheet!$A$1:$D$202,2,FALSE) -> 38
A69: China | B69: Fujian Sheng | C69: CN-FJ | D69: Province | E69: 福建省 (Fújiàn Shěng) | F69: =VLOOKUP(A69,Country_WorkingSheet!$A$1:$D$202,2,FALSE) -> 38
A70: China | B70: Guangdong Sheng | C70: CN-GD | D70: Province | E70: 广东省 (Guǎngdōng Shěng) | F70: =VLOOKUP(A70,Country_WorkingSheet!$A$1:$D$202,2,FALSE) -> 38
A71: China | B71: Gansu Sheng | C71: CN-GS | D71: Province | E71: 甘肃省 (Gānsù Shěng) | F71: =VLOOKUP(A71,Country_WorkingSheet!$A$1:$D$202,2,FALSE) -> 38
A72: China | B72: Guangxi Zhuangzu Zizhiqu | C72: CN-GX | D72: Autonomous region | E72: 广西壮族自治区 (Guǎngxī Zhuàngzú Zìzhìqū) | F72: =VLOOKUP(A72,Country_WorkingSheet!$A$1:$D$202,2,FALSE) -> 38
A73: China | B73: Guizhou Sheng | C73: CN-GZ | D73: Province | E73: 贵州省 (Guìzhōu Shěng) | F73: =VLOOKUP(A73,Country_WorkingSheet!$A$1:$D$202,2,FALSE) -> 38
A74: China | B74: Henan Sheng | C74: CN-HA | D74: Province | E74: 河南省 (Hénán Shěng) | F74: =VLOOKUP(A74,Country_WorkingSheet!$A$1:$D$202,2,FALSE) -> 38
A75: China | B75: Hubei Sheng | C75: CN-HB | D75: Province | E75: 湖北省 (Húběi Shěng) | F75: =VLOOKUP(A75,Country_WorkingSheet!$A$1:$D$202,2,FALSE) -> 38
A76: China | B76: Hebei Sheng | C76: CN-HE | D76: Province | E76: 河北省 (Héběi Shěng) | F76: =VLOOKUP(A76,Country_WorkingSheet!$A$1:$D$202,2,FALSE) -> 38
A77: China | B77: Hainan Sheng | C77: CN-HI | D77: Province | E77: 海南省 (Hǎinán Shěng) | F77: =VLOOKUP(A77,Country_WorkingSheet!$A$1:$D$202,2,FALSE) -> 38
A78: China | B78: Hong Kong SAR (en) | C78: CN-HK | D78: Special administrative region | E78: 香港特别行政区 (Xiānggǎng Tèbiéxíngzhèngqū) | F78: =VLOOKUP(A78,Country_WorkingSheet!$A$1:$D$202,2,FALSE) -> 38
A79: China | B79: Xianggang Tebiexingzhengqu (zh) | D79: Province | F79: =VLOOKUP(A79,Country_WorkingSheet!$A$1:$D$202,2,FALSE) -> 38
A80: China | B80: Heilongjiang Sheng | C80: CN-HL | D80: Province | E80: 黑龙江省 (Hēilóngjiāng Shěng) | F80: =VLOOKUP(A80,Country_WorkingSheet!$A$1:$D$202,2,FALSE) -> 38
A81: China | B81: Hunan Sheng | C81: CN-HN | D81: Province | E81: 湖南省 (Húnán Shěng) | F81: =VLOOKUP(A81,Country_WorkingSheet!$A$1:$D$202,2,FALSE) -> 38
A82: China | B82: Jilin Sheng | C82: CN-JL | D82: Province | E82: 吉林省 (Jílín Shěng) | F82: =VLOOKUP(A82,Country_WorkingSheet!$A$1:$D$202,2,FALSE) -> 38
A83: China | B83: Jiangsu Sheng | C83: CN-JS | D83: Province | E83: 江苏省 (Jiāngsū Shěng) | F83: =VLOOKUP(A83,Country_WorkingSheet!$A$1:$D$202,2,FALSE) -> 38
A84: China | B84: Jiangxi Sheng | C84: CN-JX | D84: Province | E84: 江西省 (Jiāngxī Shěng) | F84: =VLOOKUP(A84,Country_WorkingSheet!$A$1:$D$202,2,FALSE) -> 38
A85: China | B85: Liaoning Sheng | C85: CN-LN | D85: Province | E85: 辽宁省 (Liáoníng Shěng) | F85: =VLOOKUP(A85,Country_WorkingSheet!$A$1:$D$202,2,FALSE) -> 38
A86: China | B86: Macao SAR (en) | C86: CN-MO | D86: Special administrative region | E86: 澳门特别行政区 (Àomén Tèbiéxíngzhèngqū) | F86: =VLOOKUP(A86,Country_WorkingSheet!$A$1:$D$202,2,FALSE) -> 38
A87: China | B87: Macau SAR (pt) | D87: Province | F87: =VLOOKUP(A87,Country_WorkingSheet!$A$1:$D$202,2,FALSE) -> 38
A88: China | B88: Aomen Tebiexingzhengqu (zh) | D88: Province | F88: =VLOOKUP(A88,Country_WorkingSheet!$A$1:$D$202,2,FALSE) -> 38
A89: China | B89: Nei Mongol Zizhiqu (mn) | C89: CN-NM | D89: Autonomous region | E89: 内蒙古自治区 (Nèi Ménggǔ Zìzhìqū) | F89: =VLOOKUP(A89,Country_WorkingSheet!$A$1:$D$202,2,FALSE) -> 38
A90: China | B90: Ningxia Huizu Zizhiqu | C90: CN-NX | D90: Autonomous region | E90: 宁夏回族自治区 (Níngxià Huízú Zìzhìqū) | F90: =VLOOKUP(A90,Country_WorkingSheet!$A$1:$D$202,2,FALSE) -> 38
A91: China | B91: Qinghai Sheng | C91: CN-QH | D91: Province | E91: 青海省 (Qīnghǎi Shěng) | F91: =VLOOKUP(A91,Country_WorkingSheet!$A$1:$D$202,2,FALSE) -> 38
...

Sheet Sheet4
A1: Id | B1: Name | C1: Code | D1: Type | E1: LocalName | F1: CountryId
A2: 1 | B2: Buenos Aires (Ciudad) | C2: CIUDAD AUTÓNOMA DE BUENOS AIRES | D2: Province | F2: 7 | G2: =IF(E2="",B2,E2) -> Buenos Aires (Ciudad) | H2: ="new Models.State() {Name = """&B2&""", Code = """&C2&""", Id ="&A2&", CountryId = "&F2&", LocalName = """&G2&""", Type = """&D2&""" }," -> new Models.State() {Name = "Buenos Aires (Ciudad)", Code = "CIUDAD AUTÓNOMA DE BUENOS AIRES", Id =1, CountryId = 7, LocalName = "Buenos Aires (Ciudad)", Type = "Province" },
A3: =1+A2 -> 2 | B3: Buenos Aires (Provincia) | C3: BUENOS AIRES | D3: Province | F3: 7 | G3: =IF(E3="",B3,E3) -> Buenos Aires (Provincia) | H3: ="new Models.State() {Name = """&B3&""", Code = """&C3&""", Id ="&A3&", CountryId = "&F3&", LocalName = """&G3&""", Type = """&D3&""" }," -> new Models.State() {Name = "Buenos Aires (Provincia)", Code = "BUENOS AIRES", Id =2, CountryId = 7, LocalName = "Buenos Aires (Provincia)", Type = "Province" },
A4: =1+A3 -> 3 | B4: Catamarca | C4: CATAMARCA | D4: Province | F4: 7 | G4: =IF(E4="",B4,E4) -> Catamarca | H4: ="new Models.State() {Name = """&B4&""", Code = """&C4&""", Id ="&A4&", CountryId = "&F4&", LocalName = """&G4&""", Type = """&D4&""" }," -> new Models.State() {Name = "Catamarca", Code = "CATAMARCA", Id =3, CountryId = 7, LocalName = "Catamarca", Type = "Province" },
A5: =1+A4 -> 4 | B5: Chaco | C5: CHACO | D5: Province | F5: 7 | G5: =IF(E5="",B5,E5) -> Chaco | H5: ="new Models.State() {Name = """&B5&""", Code = """&C5&""", Id ="&A5&", CountryId = "&F5&", LocalName = """&G5&""", Type = """&D5&""" }," -> new Models.State() {Name = "Chaco", Code = "CHACO", Id =4, CountryId = 7, LocalName = "Chaco", Type = "Province" },
A6: =1+A5 -> 5 | B6: Chubut | C6: CHUBUT | D6: Province | F6: 7 | G6: =IF(E6="",B6,E6) -> Chubut | H6: ="new Models.State() {Name = """&B6&""", Code = """&C6&""", Id ="&A6&", CountryId = "&F6&", LocalName = """&G6&""", Type = """&D6&""" }," -> new Models.State() {Name = "Chubut", Code = "CHUBUT", Id =5, CountryId = 7, LocalName = "Chubut", Type = "Province" },
A7: =1+A6 -> 6 | B7: Corrientes | C7: CORRIENTES | D7: Province | F7: 7 | G7: =IF(E7="",B7,E7) -> Corrientes | H7: ="new Models.State() {Name = """&B7&""", Code = """&C7&""", Id ="&A7&", CountryId = "&F7&", LocalName = """&G7&""", Type = """&D7&""" }," -> new Models.State() {Name = "Corrientes", Code = "CORRIENTES", Id =6, CountryId = 7, LocalName = "Corrientes", Type = "Province" },
A8: =1+A7 -> 7 | B8: Córdoba | C8: CÓRDOBA | D8: Province | F8: 7 | G8: =IF(E8="",B8,E8) -> Córdoba | H8: ="new Models.State() {Name = """&B8&""", Code = """&C8&""", Id ="&A8&", CountryId = "&F8&", LocalName = """&G8&""", Type = """&D8&""" }," -> new Models.State() {Name = "Córdoba", Code = "CÓRDOBA", Id =7, CountryId = 7, LocalName = "Córdoba", Type = "Province" },
A9: =1+A8 -> 8 | B9: Entre Ríos | C9: ENTRE RÍOS | D9: Province | F9: 7 | G9: =IF(E9="",B9,E9) -> Entre Ríos | H9: ="new Models.State() {Name = """&B9&""", Code = """&C9&""", Id ="&A9&", CountryId = "&F9&", LocalName = """&G9&""", Type = """&D9&""" }," -> new Models.State() {Name = "Entre Ríos", Code = "ENTRE RÍOS", Id =8, CountryId = 7, LocalName = "Entre Ríos", Type = "Province" },
A10: =1+A9 -> 9 | B10: Formosa | C10: FORMOSA | D10: Province | F10: 7 | G10: =IF(E10="",B10,E10) -> Formosa | H10: ="new Models.State() {Name = """&B10&""", Code = """&C10&""", Id ="&A10&", CountryId = "&F10&", LocalName = """&G10&""", Type = """&D10&""" }," -> new Models.State() {Name = "Formosa", Code = "FORMOSA", Id =9, CountryId = 7, LocalName = "Formosa", Type = "Province" },
A11: =1+A10 -> 10 | B11: Jujuy | C11: JUJUY | D11: Province | F11: 7 | G11: =IF(E11="",B11,E11) -> Jujuy | H11: ="new Models.State() {Name = """&B11&""", Code = """&C11&""", Id ="&A11&", CountryId = "&F11&", LocalName = """&G11&""", Type = """&D11&""" }," -> new Models.State() {Name = "Jujuy", Code = "JUJUY", Id =10, CountryId = 7, LocalName = "Jujuy", Type = "Province" },
A12: =1+A11 -> 11 | B12: La Pampa | C12: LA PAMPA | D12: Province | F12: 7 | G12: =IF(E12="",B12,E12) -> La Pampa | H12: ="new Models.State() {Name = """&B12&""", Code = """&C12&""", Id ="&A12&", CountryId = "&F12&", LocalName = """&G12&""", Type = """&D12&""" }," -> new Models.State() {Name = "La Pampa", Code = "LA PAMPA", Id =11, CountryId = 7, LocalName = "La Pampa", Type = "Province" },
A13: =1+A12 -> 12 | B13: La Rioja | C13: LA RIOJA | D13: Province | F13: 7 | G13: =IF(E13="",B13,E13) -> La Rioja | H13: ="new Models.State() {Name = """&B13&""", Code = """&C13&""", Id ="&A13&", CountryId = "&F13&", LocalName = """&G13&""", Type = """&D13&""" }," -> new Models.State() {Name = "La Rioja", Code = "LA RIOJA", Id =12, CountryId = 7, LocalName = "La Rioja", Type = "Province" },
A14: =1+A13 -> 13 | B14: Mendoza | C14: MENDOZA | D14: Province | F14: 7 | G14: =IF(E14="",B14,E14) -> Mendoza | H14: ="new Models.State() {Name = """&B14&""", Code = """&C14&""", Id ="&A14&", CountryId = "&F14&", LocalName = """&G14&""", Type = """&D14&""" }," -> new Models.State() {Name = "Mendoza", Code = "MENDOZA", Id =13, CountryId = 7, LocalName = "Mendoza", Type = "Province" },
... A65: =1+A64 -> 64 | B65: Yukon | C65: YT | D65: Province | F65: 33 | G65: =IF(E65="",B65,E65) -> Yukon | H65: ="new Models.State() {Name = """&B65&""", Code = """&C65&""", Id ="&A65&", CountryId = "&F65&", LocalName = """&G65&""", Type = """&D65&""" }," -> new Models.State() {Name = "Yukon", Code = "YT", Id =64, CountryId = 33, LocalName = "Yukon", Type = "Province" },
A66: =1+A65 -> 65 | B66: Anhui Sheng | C66: CN-AH | D66: Province | E66: 安徽省 (Ānhuī Shěng) | F66: 38 | G66: =IF(E66="",B66,E66) -> 安徽省 (Ānhuī Shěng) | H66: ="new Models.State() {Name = """&B66&""", Code = """&C66&""", Id ="&A66&", CountryId = "&F66&", LocalName = """&G66&""", Type = """&D66&""" }," -> new Models.State() {Name = "Anhui Sheng", Code = "CN-AH", Id =65, CountryId = 38, LocalName = "安徽省 (Ānhuī Shěng)", Type = "Province" },
A67: =1+A66 -> 66 | B67: Beijing Shi | C67: CN-BJ | D67: Municipality | E67: 北京市 (Běijīng Shì) | F67: 38 | G67: =IF(E67="",B67,E67) -> 北京市 (Běijīng Shì) | H67: ="new Models.State() {Name = """&B67&""", Code = """&C67&""", Id ="&A67&", CountryId = "&F67&", LocalName = """&G67&""", Type = """&D67&""" }," -> new Models.State() {Name = "Beijing Shi", Code = "CN-BJ", Id =66, CountryId = 38, LocalName = "北京市 (Běijīng Shì)", Type = "Municipality" },
A68: =1+A67 -> 67 | B68: Chongqing Shi | C68: CN-CQ | D68: Municipality | E68: 重庆市 (Chóngqìng Shì) | F68: 38 | G68: =IF(E68="",B68,E68) -> 重庆市 (Chóngqìng Shì) | H68: ="new Models.State() {Name = """&B68&""", Code = """&C68&""", Id ="&A68&", CountryId = "&F68&", LocalName = """&G68&""", Type = """&D68&""" }," -> new Models.State() {Name = "Chongqing Shi", Code = "CN-CQ", Id =67, CountryId = 38, LocalName = "重庆市 (Chóngqìng Shì)", Type = "Municipality" },
A69: =1+A68 -> 68 | B69: Fujian Sheng | C69: CN-FJ | D69: Province | E69: 福建省 (Fújiàn Shěng) | F69: 38 | G69: =IF(E69="",B69,E69) -> 福建省 (Fújiàn Shěng) | H69: ="new Models.State() {Name = """&B69&""", Code = """&C69&""", Id ="&A69&", CountryId = "&F69&", LocalName = """&G69&""", Type = """&D69&""" }," -> new Models.State() {Name = "Fujian Sheng", Code = "CN-FJ", Id =68, CountryId = 38, LocalName = "福建省 (Fújiàn Shěng)", Type = "Province" },
A70: =1+A69 -> 69 | B70: Guangdong Sheng | C70: CN-GD | D70: Province | E70: 广东省 (Guǎngdōng Shěng) | F70: 38 | G70: =IF(E70="",B70,E70) -> 广东省 (Guǎngdōng Shěng) | H70: ="new Models.State() {Name = """&B70&""", Code = """&C70&""", Id ="&A70&", CountryId = "&F70&", LocalName = """&G70&""", Type = """&D70&""" }," -> new Models.State() {Name = "Guangdong Sheng", Code = "CN-GD", Id =69, CountryId = 38, LocalName = "广东省 (Guǎngdōng Shěng)", Type = "Province" },
A71: =1+A70 -> 70 | B71: Gansu Sheng | C71: CN-GS | D71: Province | E71: 甘肃省 (Gānsù Shěng) | F71: 38 | G71: =IF(E71="",B71,E71) -> 甘肃省 (Gānsù Shěng) | H71: ="new Models.State() {Name = """&B71&""", Code = """&C71&""", Id ="&A71&", CountryId = "&F71&", LocalName = """&G71&""", Type = """&D71&""" }," -> new Models.State() {Name = "Gansu Sheng", Code = "CN-GS", Id =70, CountryId = 38, LocalName = "甘肃省 (Gānsù Shěng)", Type = "Province" },
A72: =1+A71 -> 71 | B72: Guangxi Zhuangzu Zizhiqu | C72: CN-GX | D72: Autonomous region | E72: 广西壮族自治区 (Guǎngxī Zhuàngzú Zìzhìqū) | F72: 38 | G72: =IF(E72="",B72,E72) -> 广西壮族自治区 (Guǎngxī Zhuàngzú Zìzhìqū) | H72: ="new Models.State() {Name = """&B72&""", Code = """&C72&""", Id ="&A72&", CountryId = "&F72&", LocalName = """&G72&""", Type = """&D72&""" }," -> new Models.State() {Name = "Guangxi Zhuangzu Zizhiqu", Code = "CN-GX", Id =71, CountryId = 38, LocalName = "广西壮族自治区 (Guǎngxī Zhuàngzú Zìzhìqū)", Type = "Autonomous region" },
A73: =1+A72 -> 72 | B73: Guizhou Sheng | C73: CN-GZ | D73: Province | E73: 贵州省 (Guìzhōu Shěng) | F73: 38 | G73: =IF(E73="",B73,E73) -> 贵州省 (Guìzhōu Shěng) | H73: ="new Models.State() {Name = """&B73&""", Code = """&C73&""", Id ="&A73&", CountryId = "&F73&", LocalName = """&G73&""", Type = """&D73&""" }," -> new Models.State() {Name = "Guizhou Sheng", Code = "CN-GZ", Id =72, CountryId = 38, LocalName = "贵州省 (Guìzhōu Shěng)", Type = "Province" },
A74: =1+A73 -> 73 | B74: Henan Sheng | C74: CN-HA | D74: Province | E74: 河南省 (Hénán Shěng) | F74: 38 | G74: =IF(E74="",B74,E74) -> 河南省 (Hénán Shěng) | H74: ="new Models.State() {Name = """&B74&""", Code = """&C74&""", Id ="&A74&", CountryId = "&F74&", LocalName = """&G74&""", Type = """&D74&""" }," -> new Models.State() {Name = "Henan Sheng", Code = "CN-HA", Id =73, CountryId = 38, LocalName = "河南省 (Hénán Shěng)", Type = "Province" },
A75: =1+A74 -> 74 | B75: Hubei Sheng | C75: CN-HB | D75: Province | E75: 湖北省 (Húběi Shěng) | F75: 38 | G75: =IF(E75="",B75,E75) -> 湖北省 (Húběi Shěng) | H75: ="new Models.State() {Name = """&B75&""", Code = """&C75&""", Id ="&A75&", CountryId = "&F75&", LocalName = """&G75&""", Type = """&D75&""" }," -> new Models.State() {Name = "Hubei Sheng", Code = "CN-HB", Id =74, CountryId = 38, LocalName = "湖北省 (Húběi Shěng)", Type = "Province" },
A76: =1+A75 -> 75 | B76: Hebei Sheng | C76: CN-HE | D76: Province | E76: 河北省 (Héběi Shěng) | F76: 38 | G76: =IF(E76="",B76,E76) -> 河北省 (Héběi Shěng) | H76: ="new Models.State() {Name = """&B76&""", Code = """&C76&""", Id ="&A76&", CountryId = "&F76&", LocalName = """&G76&""", Type = """&D76&""" }," -> new Models.State() {Name = "Hebei Sheng", Code = "CN-HE", Id =75, CountryId = 38, LocalName = "河北省 (Héběi Shěng)", Type = "Province" },
A77: =1+A76 -> 76 | B77: Hainan Sheng | C77: CN-HI | D77: Province | E77: 海南省 (Hǎinán Shěng) | F77: 38 | G77: =IF(E77="",B77,E77) -> 海南省 (Hǎinán Shěng) | H77: ="new Models.State() {Name = """&B77&""", Code = """&C77&""", Id ="&A77&", CountryId = "&F77&", LocalName = """&G77&""", Type = """&D77&""" }," -> new Models.State() {Name = "Hainan Sheng", Code = "CN-HI", Id =76, CountryId = 38, LocalName = "海南省 (Hǎinán Shěng)", Type = "Province" },
A78: =1+A77 -> 77 | B78: Hong Kong SAR (en) | C78: CN-HK | D78: Special administrative region | E78: 香港特别行政区 (Xiānggǎng Tèbiéxíngzhèngqū) | F78: 38 | G78: =IF(E78="",B78,E78) -> 香港特别行政区 (Xiānggǎng Tèbiéxíngzhèngqū) | H78: ="new Models.State() {Name = """&B78&""", Code = """&C78&""", Id ="&A78&", CountryId = "&F78&", LocalName = """&G78&""", Type = """&D78&""" }," -> new Models.State() {Name = "Hong Kong SAR (en)", Code = "CN-HK", Id =77, CountryId = 38, LocalName = "香港特别行政区 (Xiānggǎng Tèbiéxíngzhèngqū)", Type = "Special administrative region" },
A79: =1+A78 -> 78 | B79: Xianggang Tebiexingzhengqu (zh) | D79: Province | F79: 38 | G79: =IF(E79="",B79,E79) -> Xianggang Tebiexingzhengqu (zh) | H79: ="new Models.State() {Name = """&B79&""", Code = """&C79&""", Id ="&A79&", CountryId = "&F79&", LocalName = """&G79&""", Type = """&D79&""" }," -> new Models.State() {Name = "Xianggang Tebiexingzhengqu (zh)", Code = "", Id =78, CountryId = 38, LocalName = "Xianggang Tebiexingzhengqu (zh)", Type = "Province" },
A80: =1+A79 -> 79 | B80: Heilongjiang Sheng | C80: CN-HL | D80: Province | E80: 黑龙江省 (Hēilóngjiāng Shěng) | F80: 38 | G80: =IF(E80="",B80,E80) -> 黑龙江省 (Hēilóngjiāng Shěng) | H80: ="new Models.State() {Name = """&B80&""", Code = """&C80&""", Id ="&A80&", CountryId = "&F80&", LocalName = """&G80&""", Type = """&D80&""" }," -> new Models.State() {Name = "Heilongjiang Sheng", Code = "CN-HL", Id =79, CountryId = 38, LocalName = "黑龙江省 (Hēilóngjiāng Shěng)", Type = "Province" },
A81: =1+A80 -> 80 | B81: Hunan Sheng | C81: CN-HN | D81: Province | E81: 湖南省 (Húnán Shěng) | F81: 38 | G81: =IF(E81="",B81,E81) -> 湖南省 (Húnán Shěng) | H81: ="new Models.State() {Name = """&B81&""", Code = """&C81&""", Id ="&A81&", CountryId = "&F81&", LocalName = """&G81&""", Type = """&D81&""" }," -> new Models.State() {Name = "Hunan Sheng", Code = "CN-HN", Id =80, CountryId = 38, LocalName = "湖南省 (Húnán Shěng)", Type = "Province" },
A82: =1+A81 -> 81 | B82: Jilin Sheng | C82: CN-JL | D82: Province | E82: 吉林省 (Jílín Shěng) | F82: 38 | G82: =IF(E82="",B82,E82) -> 吉林省 (Jílín Shěng) | H82: ="new Models.State() {Name = """&B82&""", Code = """&C82&""", Id ="&A82&", CountryId = "&F82&", LocalName = """&G82&""", Type = """&D82&""" }," -> new Models.State() {Name = "Jilin Sheng", Code = "CN-JL", Id =81, CountryId = 38, LocalName = "吉林省 (Jílín Shěng)", Type = "Province" },
A83: =1+A82 -> 82 | B83: Jiangsu Sheng | C83: CN-JS | D83: Province | E83: 江苏省 (Jiāngsū Shěng) | F83: 38 | G83: =IF(E83="",B83,E83) -> 江苏省 (Jiāngsū Shěng) | H83: ="new Models.State() {Name = """&B83&""", Code = """&C83&""", Id ="&A83&", CountryId = "&F83&", LocalName = """&G83&""", Type = """&D83&""" }," -> new Models.State() {Name = "Jiangsu Sheng", Code = "CN-JS", Id =82, CountryId = 38, LocalName = "江苏省 (Jiāngsū Shěng)", Type = "Province" },
A84: =1+A83 -> 83 | B84: Jiangxi Sheng | C84: CN-JX | D84: Province | E84: 江西省 (Jiāngxī Shěng) | F84: 38 | G84: =IF(E84="",B84,E84) -> 江西省 (Jiāngxī Shěng) | H84: ="new Models.State() {Name = """&B84&""", Code = """&C84&""", Id ="&A84&", CountryId = "&F84&", LocalName = """&G84&""", Type = """&D84&""" }," -> new Models.State() {Name = "Jiangxi Sheng", Code = "CN-JX", Id =83, CountryId = 38, LocalName = "江西省 (Jiāngxī Shěng)", Type = "Province" },
A85: =1+A84 -> 84 | B85: Liaoning Sheng | C85: CN-LN | D85: Province | E85: 辽宁省 (Liáoníng Shěng) | F85: 38 | G85: =IF(E85="",B85,E85) -> 辽宁省 (Liáoníng Shěng) | H85: ="new Models.State() {Name = """&B85&""", Code = """&C85&""", Id ="&A85&", CountryId = "&F85&", LocalName = """&G85&""", Type = """&D85&""" }," -> new Models.State() {Name = "Liaoning Sheng", Code = "CN-LN", Id =84, CountryId = 38, LocalName = "辽宁省 (Liáoníng Shěng)", Type = "Province" },
A86: =1+A85 -> 85 | B86: Macao SAR (en) | C86: CN-MO | D86: Special administrative region | E86: 澳门特别行政区 (Àomén Tèbiéxíngzhèngqū) | F86: 38 | G86: =IF(E86="",B86,E86) -> 澳门特别行政区 (Àomén Tèbiéxíngzhèngqū) | H86: ="new Models.State() {Name = """&B86&""", Code = """&C86&""", Id ="&A86&", CountryId = "&F86&", LocalName = """&G86&""", Type = """&D86&""" }," -> new Models.State() {Name = "Macao SAR (en)", Code = "CN-MO", Id =85, CountryId = 38, LocalName = "澳门特别行政区 (Àomén Tèbiéxíngzhèngqū)", Type = "Special administrative region" },
A87: =1+A86 -> 86 | B87: Macau SAR (pt) | D87: Province | F87: 38 | G87: =IF(E87="",B87,E87) -> Macau SAR (pt) | H87: ="new Models.State() {Name = """&B87&""", Code = """&C87&""", Id ="&A87&", CountryId = "&F87&", LocalName = """&G87&""", Type = """&D87&""" }," -> new Models.State() {Name = "Macau SAR (pt)", Code = "", Id =86, CountryId = 38, LocalName = "Macau SAR (pt)", Type = "Province" },
A88: =1+A87 -> 87 | B88: Aomen Tebiexingzhengqu (zh) | D88: Province | F88: 38 | G88: =IF(E88="",B88,E88) -> Aomen Tebiexingzhengqu (zh) | H88: ="new Models.State() {Name = """&B88&""", Code = """&C88&""", Id ="&A88&", CountryId = "&F88&", LocalName = """&G88&""", Type = """&D88&""" }," -> new Models.State() {Name = "Aomen Tebiexingzhengqu (zh)", Code = "", Id =87, CountryId = 38, LocalName = "Aomen Tebiexingzhengqu (zh)", Type = "Province" },
A89: =1+A88 -> 88 | B89: Nei Mongol Zizhiqu (mn) | C89: CN-NM | D89: Autonomous region | E89: 内蒙古自治区 (Nèi Ménggǔ Zìzhìqū) | F89: 38 | G89: =IF(E89="",B89,E89) -> 内蒙古自治区 (Nèi Ménggǔ Zìzhìqū) | H89: ="new Models.State() {Name = """&B89&""", Code = """&C89&""", Id ="&A89&", CountryId = "&F89&", LocalName = """&G89&""", Type = """&D89&""" }," -> new Models.State() {Name = "Nei Mongol Zizhiqu (mn)", Code = "CN-NM", Id =88, CountryId = 38, LocalName = "内蒙古自治区 (Nèi Ménggǔ Zìzhìqū)", Type = "Autonomous region" },
A90: =1+A89 -> 89 | B90: Ningxia Huizu Zizhiqu | C90: CN-NX | D90: Autonomous region | E90: 宁夏回族自治区 (Níngxià Huízú Zìzhìqū) | F90: 38 | G90: =IF(E90="",B90,E90) -> 宁夏回族自治区 (Níngxià Huízú Zìzhìqū) | H90: ="new Models.State() {Name = """&B90&""", Code = """&C90&""", Id ="&A90&", CountryId = "&F90&", LocalName = """&G90&""", Type = """&D90&""" }," -> new Models.State() {Name = "Ningxia Huizu Zizhiqu", Code = "CN-NX", Id =89, CountryId = 38, LocalName = "宁夏回族自治区 (Níngxià Huízú Zìzhìqū)", Type = "Autonomous region" },
...
